Workbook
Name TOTALDU: #REF!

Sheet Index
C4: Upstate House, LLC
C5: 46113
C8: CONTENTS | D8: Description
C9: Assumptions
C10: Unit Mix
C11: Sources and Uses
C12: Mortgage
C13: Construction Interest
C14: Operating Expenses & Reserves
C15: Taxcredit Analysis
C16: Budget
C17: Development Cash flow
C18: Rental Cash flow
C19: Debt Schedule
C20: KPI's
C22: COLOR CODING | D22: TEXT COLOR
C23: Inputs/assumptions | D23: BLUE | E23: Inputs, or any hard-coded data, such as historical values, assumptions, and drivers.
C24: Formulas/results | D24: BLACK | E24: Formulas, calculations, or references deriving from inputs
C25: Regulatory Requirements | D25: GREEN | E25: Requirement as per NCF, HPD or IRS.
C26: Market Rates | D26: ORANGE | E26: Requirement as per latest target Market standards

Sheet Assumptions
B2: Assumptions
B4: All input cells are in Yellow
B6: Project Timeline
B8: Model start date | C8: 46204
B9: No. of months (Pre Development phase) | C9: 6 | D9: months
B10: Development start date | C10: =EOMONTH(C8,C9) -> 46418
B11: No. of months (Development phase) | C11: 24 | D11: months
B12: Rent up an conversion | C12: 6 | D12: months
B13: Rent start Date (Post construction phase) | C13: =EOMONTH(C10,(C11+C12)) -> 47330
B14: No. of months | C14: =30*12 -> 360 | D14: months
B15: Exit date | C15: =EOMONTH(C13,C14) -> 58287
B16: Total Holding Period | C16: =ROUND((C15-C8)/365.25,0) -> 33 | D16: years
B19: Checklist
B20: Maximum average AMI | C20: =(D34*B34)+(D35*B35)+(B36*D36)+(B37*D37)+(B38*D38) -> 0.575 | D20: =IF(C20<=60%,"OK","check") -> OK
B21: Distributed and Allocated Units | C21: =IF(C39='Unit Mix'!H82,"EQUAL","UNEQUAL") -> EQUAL | D21: =IF(C21="EQUAL","OK","check") -> OK
B23: Design
B24: 63 | C24: Studio | D24: =B24/$B$28 -> 0.19207317 | E24: Max 25% Studio
B25: 58 | C25: 1 Bedroom | D25: =B25/$B$28 -> 0.17682927 | E25: Min 15% 1BR
B26: 128 | C26: 2 Bedroom | D26: =B26/$B$28 -> 0.3902439 | E26: Min 30% 2BR+
B27: 79 | C27: 3 Bedroom | D27: =B27/$B$28 -> 0.24085366
B28: =SUM(B24:B27) -> 328 | D28: =B28/$B$28 -> 1
B29: 1 | C29: Super's Unit
B30: =SUM(B28:B29) -> 329
B32: Distribution by AMI
B33: AMI Tier | C33: Units | D33: %
B34: 0.3 | C34: =ROUND($B$28*D34,0) -> 49 | D34: 0.15 | E34: 15-30% as per NCF
B35: 0.4 | C35: =ROUND($B$28*D35,0) -> 82 | D35: 0.25
B36: 0.6 | C36: =ROUND($B$28*D36,0) -> 82 | D36: 0.25
B37: 0.8 | C37: =B28-SUM(C34:C36) -> 115 | D37: 0.35
B38: 0 | C38: =$B$28*D38 -> 0 | D38: =0 -> 0 | E38: Max. 4 tiers as per NCF
B39: Total | C39: =SUM(C34:C38) -> 328 | D39: =SUM(D34:D38) -> 1
B42: Gross Sqare foot Distribution
B43: Residential GSF | C43: 305300
B44: Commercial GSF | C44: 0
B45: Community GSF | C45: 18000
B46: Parking GSF | C46: 0
B47: Total GSF | C47: =SUM(C43:C46) -> 323300
B49: Price PSF (Target Location)
B50: Residential Price per square foot | C50: 540
B51: Non-Residential Price per square foot | C51: 350
...

Sheet Unit Mix
B3: Design | F3: Total units | G3: =C19 -> 328
B4: =Assumptions!B24 -> 63 | C4: Studio | D4: =B4/SUM($B$4:$B$7) -> 0.19207317
B5: =Assumptions!B25 -> 58 | C5: 1 Bedroom | D5: =B5/SUM($B$4:$B$7) -> 0.17682927
B6: =Assumptions!B26 -> 128 | C6: 2 Bedroom | D6: =B6/SUM($B$4:$B$7) -> 0.3902439
B7: =Assumptions!B27 -> 79 | C7: 3 Bedroom | D7: =B7/SUM($B$4:$B$7) -> 0.24085366
B8: =SUM(B4:B7) -> 328 | D8: =B8/SUM($B$4:$B$7) -> 1
B9: =Assumptions!B29 -> 1 | C9: Super Unit
B10: =SUM(B8:B9) -> 329
B12: Summary
B13: AMI Tier | C13: Units | D13: %
B14: =Assumptions!B34 -> 0.3 | C14: =Assumptions!C34 -> 49 | D14: =Assumptions!D34 -> 0.15
B15: =Assumptions!B35 -> 0.4 | C15: =Assumptions!C35 -> 82 | D15: =Assumptions!D35 -> 0.25
B16: =Assumptions!B36 -> 0.6 | C16: =Assumptions!C36 -> 82 | D16: =Assumptions!D36 -> 0.25
B17: =Assumptions!B37 -> 0.8 | C17: =Assumptions!C37 -> 115 | D17: =Assumptions!D37 -> 0.35
B18: =Assumptions!B38 -> 0 | C18: =Assumptions!C38 -> 0 | D18: =Assumptions!D38 -> 0
B19: Total | C19: =SUM(C14:C18) -> 328 | D19: =SUM(D14:D18) -> 1
B21: Unit size | C21: Net Square Footage
C22: Min | D22: Max
B23: Studio | C23: 350 | D23: 400 | E23: sqft
B24: 1 Bedroom | C24: 500 | D24: 550 | E24: sqft
B25: 2 Bedroom | C25: 650 | D25: 725 | E25: sqft
B26: 3 Bedroom | C26: 850 | D26: 950 | E26: sqft
B27: 4 Bedroom | C27: 950 | D27: 1075 | E27: sqft
B30: UNIT DISTRIBUTION
C31: Number of units | D31: Number of Rooms per unit | E31: Total rooms | F31: Avg NSF/Unit
B32: Studio | C32: =B4 -> 63 | D32: 2 | E32: =C32*D32 -> 126 | F32: =AVERAGE(C23,D23) -> 375
B33: 1 Bedroom | C33: =B5 -> 58 | D33: 3 | E33: =C33*D33 -> 174 | F33: =AVERAGE(C24,D24) -> 525
B34: 2 Bedroom | C34: =B6 -> 128 | D34: 4 | E34: =C34*D34 -> 512 | F34: =AVERAGE(C25,D25) -> 687.5
B35: 3 Bedroom | C35: =B7 -> 79 | D35: 5 | E35: =C35*D35 -> 395 | F35: =AVERAGE(C26,D26) -> 900
B36: 4 Bedroom | C36: 0 | D36: 0 | E36: =C36*D36 -> 0
B37: Subtotal | C37: =SUM(C32:C36) -> 328 | E37: =SUM(E32:E36) -> 1207 | F37: =SUM(F32:F36) -> 2487.5
B38: Super's Unit | C38: 1 | E38: 0
B39: Total | C39: =C37+C38 -> 329 | E39: =SUM(E37:E38) -> 1207 | F39: =C32*F32+C33*F33+C34*F34+C35*F35+C38*F38 -> 213175
B41: Unit Allocation Matrix
C42: {=TRANSPOSE(B14:B18)} -> 0.3 | D42: 0.4 | E42: 0.6 | F42: 0.8 | G42: 0
B43: =B23 -> Studio | C43: =Assumptions!$C$34*Assumptions!$D24 -> 9.4115854 | D43: =Assumptions!$C$35*Assumptions!$D24 -> 15.75 | E43: =Assumptions!$C$36*Assumptions!$D24 -> 15.75 | F43: =B4-SUM(C43+D43+E43) -> 22.088415 | G43: =Assumptions!$B$38*Assumptions!$D24 -> 0
B44: =B24 -> 1 Bedroom | C44: =Assumptions!$C$34*Assumptions!$D25 -> 8.6646341 | D44: =Assumptions!$C$35*Assumptions!$D25 -> 14.5 | E44: =Assumptions!$C$36*Assumptions!$D25 -> 14.5 | F44: =B5-SUM(C44+D44+E44) -> 20.335366 | G44: =Assumptions!$B$38*Assumptions!$D25 -> 0
B45: =B25 -> 2 Bedroom | C45: =Assumptions!$C$34*Assumptions!$D26 -> 19.121951 | D45: =Assumptions!$C$35*Assumptions!$D26 -> 32 | E45: =Assumptions!$C$36*Assumptions!$D26 -> 32 | F45: =B6-SUM(C45+D45+E45) -> 44.878049 | G45: =Assumptions!$B$38*Assumptions!$D26 -> 0
B46: =B26 -> 3 Bedroom | C46: =Assumptions!$C$34*Assumptions!$D27 -> 11.801829 | D46: =Assumptions!$C$35*Assumptions!$D27 -> 19.75 | E46: =Assumptions!$C$36*Assumptions!$D27 -> 19.75 | F46: =B7-SUM(C46+D46+E46) -> 27.698171 | G46: =Assumptions!$B$38*Assumptions!$D27 -> 0
B47: =B27 -> 4 Bedroom | C47: =Assumptions!C38*Assumptions!D24 -> 0 | D47: =Assumptions!$C$38*Assumptions!D25 -> 0 | E47: =Assumptions!$C$38*Assumptions!D26 -> 0 | F47: =Assumptions!$C$38*Assumptions!D27 -> 0 | G47: =Assumptions!$B$38*Assumptions!$D28 -> 0
...

Sheet Sources and Uses
B2: SOURCES AND USES | D2: Units: | E2: ='Unit Mix'!C19 -> 328
B4: Construction Sources | D4: Per DU | E4: % of Total
B5: HFA First Mortgage | C5: =Mortgage!C48 -> 47186010 | D5: =C5/'Unit Mix'!$C$19 -> 143859.79 | E5: =C5/$C$12 -> 0.18382958
B6: HFA Construction Loan | C6: 1.3503435e+08 | D6: =C6/'Unit Mix'!$C$19 -> 411690.09 | E6: =C6/$C$12 -> 0.52607346
B7: NCF | C7: =Mortgage!D64 -> 47232000 | D7: =C7/'Unit Mix'!$C$19 -> 144000 | E7: =C7/$C$12 -> 0.18400875
B8: LIHTC | C8: ='Tax Credit Analysis'!D8*Assumptions!C159 -> 10635591 | D8: =C8/'Unit Mix'!$C$19 -> 32425.583 | E8: =C8/$C$12 -> 0.041434659
B9: Sponsor's Equity | C9: =Assumptions!C156 -> 0 | D9: =C9/'Unit Mix'!$C$19 -> 0 | E9: =C9/$C$12 -> 0
B10: SLIHTC | C10: 7815499.3 | D10: =C10/'Unit Mix'!$C$19 -> 23827.742 | E10: =C10/$C$12 -> 0.030448006 | F10: =C10/C18 -> 0.18277796
B11: Deferred Developer Fee | C11: =Assumptions!D62 -> 8780000 | D11: =C11/'Unit Mix'!$C$19 -> 26768.293 | E11: =C11/$C$12 -> 0.034205555
B12: Total Construction Sources | C12: =SUM(C5:C11) -> 2.5668345e+08 | D12: =C12/'Unit Mix'!$C$19 -> 782571.5 | E12: =C12/$C$12 -> 1
B14: Permament Sources | D14: Per DU | E14: % of Total
B15: HFA First Mortgage | C15: =Mortgage!C48 -> 47186010 | D15: =C15/'Unit Mix'!$C$19 -> 143859.79 | E15: =C15/$C$20 -> 0.18382958
B16: NCF | C16: =Mortgage!C63 -> 52480000 | D16: =C16/'Unit Mix'!$C$19 -> 160000 | E16: =C16/$C$20 -> 0.20445416
B17: LIHTC | C17: ='Tax Credit Analysis'!D8 -> 1.0635591e+08 | D17: =C17/'Unit Mix'!$C$19 -> 324255.83 | E17: =C17/$C$20 -> 0.41434659
B18: SLIHTC | C18: 42759527 | D18: =C18/'Unit Mix'!$C$19 -> 130364.41 | E18: =C18/$C$20 -> 0.16658467
B19: Deferred Developer Fee | C19: =Assumptions!D65 -> 7902000 | D19: =C19/'Unit Mix'!$C$19 -> 24091.463 | E19: =C19/$C$20 -> 0.030785
B20: Total Permanent Sources | C20: =SUM(C15:C19) -> 2.5668345e+08 | D20: =C20/'Unit Mix'!$C$19 -> 782571.5 | E20: =C20/$C$20 -> 1
B22: Uses | D22: Per DU | E22: % of Total
B23: Acquisition | C23: 1 | D23: 0.017241379 | E23: =C23/$C$29 -> 3.8958491e-09
B24: Hard Costs | C24: =Assumptions!C92-Assumptions!C85 -> 205394400 | D24: =C24/'Unit Mix'!$C$19 -> 626202.44 | E24: =C24/$C$29 -> 0.80018559
B25: Soft Costs | C25: =Assumptions!C118-Assumptions!C108 -> 7703079.8 | D25: =C25/'Unit Mix'!$C$19 -> 23484.999 | E25: =C25/$C$29 -> 0.030010037
B26: =Assumptions!B120 -> Finance Cost | C26: =Assumptions!C144 -> 32856072 | D26: =C26/'Unit Mix'!$C$19 -> 100170.95 | E26: =C26/$C$29 -> 0.1280023
B27: Reserves and Escrows | C27: =Assumptions!C148 -> 1949898.8 | D27: =C27/'Unit Mix'!$C$19 -> 5944.8133 | E27: =C27/$C$29 -> 0.0075965114
B28: Developer Fee | C28: =Assumptions!D62 -> 8780000 | D28: =C28/'Unit Mix'!$C$19 -> 26768.293 | E28: =C28/$C$29 -> 0.034205555
B29: TOTAL USES | C29: =SUM(C23:C28) -> 2.5668345e+08 | D29: =C29/'Unit Mix'!$C$19 -> 782571.5 | E29: =C29/$C$29 -> 1

Sheet Mortgage
B2: MORTGAGE
B4: Income
B5: Residential Income | D5: ='Unit Mix'!I81 -> 7752009.3
B6: Parking | D6: ='Unit Mix'!F97 -> 45000
B7: Commercial | D7: ='Unit Mix'!F98 -> 0
B8: Community Facility | D8: ='Unit Mix'!F99 -> 0
B9: Laundry | D9: ='Unit Mix'!F100 -> 39480
B10: Potential Gross Income (PGI) | D10: =SUM(D5:D9) -> 7836489.3
C11: HFA/SONYMA Std:
B12: Less Vacancies
B13: Total Annual Rental Income | C13: 0.05 | D13: =D5*-C13 -> -387600.46
B14: Parking | C14: 0.05 | D14: =D6*-C14 -> -2250
B15: Commercial | C15: 0.1 | D15: =D7*-C15 -> 0
B16: Community Facility | C16: 0.1 | D16: =D8*-C16 -> 0
B17: Laundry | C17: 0.1 | D17: =D9*-C17 -> -3948
B18: Net Residential Income | D18: =D5+D13 -> 7364408.8
B19: Net Comm & Ancillary Income | D19: =SUM(D6:D9)+SUM(D14:D17) -> 78282
B20: Effective Gross Income (EGI) | D20: =D18+D19 -> 7442690.8
B22: Total Expenses & Reserves | D22: ='Operating Expenses & Reserves'!D46+'Operating Expenses & Reserves'!D48 -> 3340897.3
B24: NET OPERATING INCOME (NOI) | D24: =D20-D22 -> 4101793.5
B27: PERMANENT LOAN SIZING
B28: Permanent Credit Enhancer | C28: SONYMA-MIF
B29: Loan type | C29: Tax-Exempt | D29: Self-Amortizing
B30: Interest Rate | C30: Fixed
B31: Term (years) | C31: 30
B32: Interest Rates
B33: Base Underwriting Rate | C33: 0.05
B34: Servicing Fee (HFA) | C34: 0.0025
B35: SONYMA premium | C35: =IF(C28="SONYMA-MIF",0.5%,0) -> 0.005
B36: Sum (All-In Rate): | C36: =SUM(C33:C35) -> 0.0575
B38: Debt Service Coverage Ratio (DSCR): | C38: 1.15
B39: Avail. debt service (NOI): | C39: =D24/C38 -> 3566777
B40: Max. Loan based on DSCR: | C40: =((-PV(C36/12,C31*12,(C39-C69)/12))) -> 47186010
B42: Income to Expense (I-E) Ratio (min) | C42: 1.05
B43: Effective Gross Income (EGI) | C43: =D20 -> 7442690.8
B44: Total Expenses | C44: =-D22 -> -3340897.3
B45: Avai. Debt service (I-E) | C45: =C43/C42+C44 -> 3747379.7
B46: Max. Loan based on I-E | C46: =-(PV(C38/12,C31*12,(C45+C69)/12)) -> 3486764.9
B48: HFA First Mortgage Amount | C48: =C40 -> 47186010
B50: Short term Bond Sizing
...

Sheet Construction Interest
B2: Construction Interest
B4: Loan Amount
C5: Amount | D5: % of Bond
B6: Long Term Bond | C6: =Mortgage!C48 -> 47186010 | D6: =C6/SUM($C$6:$C$7) -> 0.25895026
B7: Short Term Bond | C7: ='Sources and Uses'!C6 -> 1.3503435e+08 | D7: =C7/SUM($C$6:$C$7) -> 0.74104974
B8: Total Bond | C8: =C6+C7 -> 1.8222036e+08
B10: Subsidy Loan (NCF) | C10: =Mortgage!D64 -> 47232000
B13: Loan Term (in months)
C14: Months | D14: Years
B15: Construction Period | C15: =Assumptions!C11 -> 24 | D15: =C15/12 -> 2
B16: Rent-up and conversion | C16: =Assumptions!C12 -> 6 | D16: =C16/12 -> 0.5
B17: Total | C17: =C15+C16 -> 30 | D17: =D16+D15 -> 2.5
B20: Construction Loan (Long term) IR
B21: Base Rate (Municipal Bond) | C21: 0.05
B22: Servicing Fee (adjusted in soft cost) | C22: 0
B23: Total Long term IR | C23: =C22+C21 -> 0.05
B25: Construction Loan (NCF) IR
B26: Interest | C26: 0.005
B27: Servicing Fee (optional) | C27: 0.0025
B28: Total NCF IR | C28: =C26 -> 0.005
B31: Loan Interest Rates during Construction
B32: Long Term | C32: =C23 -> 0.05
B33: Short Term | C33: 0.042
B34: Subsidy Loan (NCF) | C34: =C28 -> 0.005
B36: Construction Interest Calculation
C37: Loan Amount | D37: Interest Rate | E37: Monthly Interest | F37: Term (months) | G37: Total
B38: Long Term | C38: =C6 -> 47186010 | D38: =C32 -> 0.05 | E38: =(C38*D38)/12 -> 196608.38 | F38: =$C$17 -> 30 | G38: =E38*F38 -> 5898251.3
B39: Short Term | C39: =C7 -> 1.3503435e+08 | D39: =C33 -> 0.042 | E39: =(C39*D39)/12 -> 472620.23 | F39: =$C$17 -> 30 | G39: =E39*F39 -> 14178607
B40: Subsidy Loan (NCF) | C40: =C10 -> 47232000 | D40: =C34 -> 0.005 | E40: =(C40*D40)/12 -> 19680 | F40: =$C$17 -> 30 | G40: =E40*F40 -> 590400
B43: Letter of Credit (LC)
B44: Bond amount | C44: =C8 -> 1.8222036e+08
B45: Days Interest | C45: =SUM(E38:E39) -> 669228.6
B46: LC amount | C46: =SUM(C44:C45) -> 1.8288959e+08
B48: LC Origination Fee (%) | C48: 0.01 | D48: HFA stds
B49: LC Annual Fee (%) | C49: 0.011 | D49: HFA stds

Sheet Operating Expenses & Reserves
B2: Management & Operating Expense
D3: Units | E3: ='Unit Mix'!C19 -> 328
D4: Rooms | E4: ='Unit Mix'!E37 -> 1207
B6: Please add/modify categories as needed: | C6: Multiplier | D6: Expenses/ Unit | E6: Expenses/ Room | F6: Borrower Projected Expenses | H6: Multiplier | I6: 2024 New Construction Standards Non-Union Building Staff | J6: Multiplier | K6: 2024 New Construction Standards Union Building Staff
B7: Fixed Expenses
B8: Real Estate Taxes | C8: per total project | D8: =F8/$E$3 -> 0 | E8: =F8/$E$4 -> 0 | F8: 0 | H8: per total project | I8: 0 | J8: per total project | K8: 0
B9: Fire & Liability Insurance | C9: per total project | D9: =F9/$E$3 -> 1500 | E9: =F9/$E$4 -> 407.6222 | F9: =I9*$E$3 -> 492000 | H9: per unit | I9: 1500 | J9: per unit | K9: =I9 -> 1500
B10: Total | D10: =SUM(D8:D9) -> 1500 | E10: =SUM(E8:E9) -> 407.6222 | F10: =SUM(F8:F9) -> 492000
B11: Administrative
B12: Accounting | C12: per total project | D12: =F12/$E$3 -> 57.926829 | E12: =F12/$E$4 -> 15.741508 | F12: =I12 -> 19000 | H12: per total project | I12: 19000 | J12: per total project | K12: =I12 -> 19000
B13: Benchmarking | C13: per total project | D13: =F13/$E$3 -> 2.4390244 | E13: =F13/$E$4 -> 0.66280033 | F13: =I13 -> 800 | H13: per total project | I13: 800 | J13: per total project | K13: =I13 -> 800
B14: Legal | C14: per total project | D14: =F14/$E$3 -> 260 | E14: =F14/$E$4 -> 70.654515 | F14: =I14*$E$3 -> 85280 | H14: per unit | I14: 260 | J14: per unit | K14: =I14 -> 260
B15: Total | D15: =SUM(D12:D14) -> 320.36585 | E15: =SUM(E12:E14) -> 87.058824 | F15: =SUM(F12:F14) -> 105080
B17: Management Fee | C17: per total project | D17: =F17/$E$3 -> 1474.9235 | E17: =F17/$E$4 -> 400.80771 | F17: =I17*Mortgage!D20 -> 483774.9 | H17: percent of EGI | I17: 0.065 | J17: percent of EGI | K17: 0.065
B19: Wi-Fi Service | C19: per unit | D19: =F19/$E$3 -> 198.17073 | E19: =F19/$E$4 -> 53.852527 | F19: =65000 -> 65000 | H19: per unit | I19: 500 | J19: per unit | K19: 400
B21: Utilities
B22: Heating | C22: per total project | D22: =F22/$E$3 -> 699.17683 | E22: =F22/$E$4 -> 190 | F22: =I22*$E$4 -> 229330 | H22: per room | I22: 190 | J22: per room | K22: =I22 -> 190
B23: Gas and Electricity | C23: per total project | D23: =F23/$E$3 -> 809.57317 | E23: =F23/$E$4 -> 220 | F23: =I23*$E$4 -> 265540 | H23: per room | I23: 220 | J23: per room | K23: =I23 -> 220
B24: Water/Sewer | C24: per total project | D24: =F24/$E$3 -> 1287.9573 | E24: =F24/$E$4 -> 350 | F24: =I24*$E$4 -> 422450 | H24: per room | I24: 350 | J24: per room | K24: =I24 -> 350
B25: Total | D25: =SUM(D22:D24) -> 2796.7073 | E25: =SUM(E22:E24) -> 760 | F25: =SUM(F22:F24) -> 917320
B26: Repairs and Maintenance
B27: Supplies/Cleaning/Exterminating | C27: per total project | D27: =F27/$E$3 -> 588.78049 | E27: =F27/$E$4 -> 160 | F27: =I27*$E$4 -> 193120 | H27: per room | I27: 160 | J27: per room | K27: =I27 -> 160
B28: Repairs/Replacement | C28: per total project | D28: =F28/$E$3 -> 1500 | E28: =F28/$E$4 -> 407.6222 | F28: =I28*$E$3 -> 492000 | H28: per unit | I28: 1500 | J28: per unit | K28: =I28 -> 1500
B29: Superintendent & Maintenance Staff Salaries | C29: per total project | D29: =F29/$E$3 -> 795.67378 | E29: =F29/$E$4 -> 216.22287 | F29: =F31+F32 -> 260981 | H29: per unit | J29: per unit
C30: Salaries | D30: No. | F30: No.
B31: Super | D31: 1 | F31: 145455
B32: Porter | D32: 7 | F32: 115526
B33: Elevator Maintenance and Repairs | C33: per elevator | D33: 3 | F33: =I33*D33 -> 24000 | H33: per elevator | I33: 8000 | J33: per elevator | K33: =I33 -> 8000
B34: Total | D34: =SUM(D27:D29) -> 2884.4543 | E34: =SUM(E27:E29) -> 783.84507 | F34: =SUM(F27:F33) -> 1231082
B36: Total Operating Expenses | D36: =D15+D17+D25+D34+D10 -> 8976.4509 | E36: =E15+E17+E25+E34+E10 -> 2439.3338 | F36: =F10+F15+F17+F25+F34 -> 3229256.9
B37: Total Expenses Net of Management Fee | D37: =D36-D10 -> 7476.4509 | E37: =E36-E10 -> 2031.7116 | F37: =F36-F17 -> 2745482
B40: Total Operating Expenses | D40: =D36 -> 8976.4509 | E40: =E36 -> 2439.3338 | F40: =F36 -> 3229256.9 | H40: 1 Staff Member for every 65 units. As permitted by law, additional FT or PT Supers or Porters may satisfy the operational needs of bulidings between each 65 unit threshold. | J40: 1 Staff Member for every 65 units. As permitted by law, additional FT or PT Supers or Porters may satisfy the operational needs of bulidings between each 65 unit threshold.
B44: Reserves
D45: Annually
B46: Opertaing Expense | D46: ='Operating Expenses & Reserves'!F36 -> 3229256.9
B47: Operating Reserve | C47: 6 months M&O + debt service | D47: =(D46/2)+(SUM('Construction Interest'!E38:E39,(Mortgage!C63*0.5%)*'Construction Interest'!D40)/2) -> 1949898.8
B48: Replacement Reserve | C48: Per annual HDC M&O standards | D48: =Mortgage!D20*1.5% -> 111640.36
B49: Social Services Reserve (Our Space) | C49: $15,000 max per Our Space unit | D49: 0
B50: Social Services Reserve Cap | C50: 3 years × $5,000/unit = $15,000/unit | D50: =15000*'Unit Mix'!C14 -> 735000
B51: Social Services Budget (Initial) | C51: $7,500 per Our Space unit | D51: =Assumptions!C34*7500 -> 367500
...

Sheet Tax Credit Analysis
B2: TAX CREDIT ANALYSIS
B3: Eligible Basis | D3: =Assumptions!F150 -> 2.4262231e+08
B4: Eligible Basis with Boost | C4: 1.3 | D4: =D3*C4 -> 3.15409e+08
B5: Applicable Fraction | C5: 1 | D5: =D4*C5 -> 3.15409e+08
B6: Annual Credit Rate | C6: 0.04 | D6: =D5*C6 -> 12616360
B7: Amount Raised per Credit | C7: 0.843 | D7: =D6*C7 -> 10635591
B8: Amount Raised Total | D8: =D7*10 -> 1.0635591e+08 | E8: Federal
B9: Amount Raised per Credit | C9: 0.65 | D9: =D6*C9 -> 8200633.9
B10: Amount Raised Total | D10: =D9*10 -> 82006339 | E10: SLIHC

Sheet Budget
B2: BUDGET
B3: ALL figures are in USD
J5: 1 | K5: 2 | L5: 3 | M5: 4 | N5: 5 | O5: 6 | P5: 7 | Q5: 8 | R5: 9 | S5: 10 | T5: 11 | U5: 12 | V5: 13 | W5: 14 | X5: 15 | Y5: 16 | Z5: 17 | AA5: 18 | AB5: 19 | AC5: 20 | AD5: 21 | AE5: 22 | AF5: 23 | AG5: 24 | AH5: 25 | AI5: 26 | AJ5: 27 | AK5: 28 | AL5: 29 | AM5: 30 | AN5: 31 | AO5: 32 | AP5: 33 | AQ5: 34 | AR5: 35 | AS5: 36 | AT5: 37 | AU5: 38 | AV5: 39 | AW5: 40 | AX5: 41 | AY5: 42 | AZ5: 43 | BA5: 44 | BB5: 45 | BC5: 46 | BD5: 47 | BE5: 48 | BF5: 49 | BG5: 50 | BH5: 51 | BI5: 52 | BJ5: 53 | BK5: 54 | BL5: 55 | BM5: 56 | BN5: 57 | BO5: 58 | BP5: 59 | BQ5: 60 | BR5: 61 | BS5: 62 | BT5: 63 | BU5: 64 | BV5: 65 | BW5: 66 | BX5: 67 | BY5: 68 | BZ5: 69 | CA5: 70 | CB5: 71 | CC5: 72 | CD5: 73 | CE5: 74 | CF5: 75 | CG5: 76 | CH5: 77 | CI5: 78 | CJ5: 79 | CK5: 80 | CL5: 81 | CM5: 82 | CN5: 83 | CO5: 84 | CP5: 85 | CQ5: 86 | CR5: 87 | CS5: 88 | CT5: 89 | CU5: 90 | CV5: 91 | CW5: 92 | CX5: 93 | CY5: 94 | CZ5: 95 | DA5: 96 | DB5: 97 | DC5: 98 | DD5: 99 | DE5: 100 | DF5: 101 | DG5: 102 | DH5: 103 | DI5: 104 | DJ5: 105 | DK5: 106 | DL5: 107 | DM5: 108 | DN5: 109 | DO5: 110 | DP5: 111 | DQ5: 112 | DR5: 113 | DS5: 114 | DT5: 115 | DU5: 116 | DV5: 117 | DW5: 118 | DX5: 119 | DY5: 120 | DZ5: 121 | EA5: 122 | EB5: 123 | EC5: 124 | ED5: 125 | EE5: 126 | EF5: 127 | EG5: 128 | EH5: 129 | EI5: 130 | EJ5: 131 | EK5: 132 | EL5: 133 | EM5: 134 | EN5: 135 | EO5: 136 | EP5: 137 | EQ5: 138 | ER5: 139 | ES5: 140 | ET5: 141 | EU5: 142 | EV5: 143 | EW5: 144 | EX5: 145 | EY5: 146 | EZ5: 147 | FA5: 148 | FB5: 149 | FC5: 150 | FD5: 151 | FE5: 152 | FF5: 153 | FG5: 154 | FH5: 155 | FI5: 156 | FJ5: 157 | FK5: 158 | FL5: 159 | FM5: 160 | FN5: 161 | FO5: 162 | FP5: 163 | FQ5: 164 | FR5: 165 | FS5: 166 | FT5: 167 | FU5: 168 | FV5: 169 | FW5: 170 | FX5: 171 | FY5: 172 | FZ5: 173 | GA5: 174 | GB5: 175 | GC5: 176 | GD5: 177 | GE5: 178 | GF5: 179 | GG5: 180 | GH5: 181 | GI5: 182 | GJ5: 183 | GK5: 184 | GL5: 185 | GM5: 186 | GN5: 187 | GO5: 188 | GP5: 189 | GQ5: 190 | GR5: 191 | GS5: 192 | GT5: 193 | GU5: 194 | GV5: 195 | GW5: 196 | GX5: 197 | GY5: 198 | GZ5: 199 | HA5: 200 | HB5: 201 | HC5: 202 | HD5: 203 | HE5: 204 | HF5: 205 | HG5: 206 | HH5: 207 | HI5: 208 | HJ5: 209 | HK5: 210 | HL5: 211 | HM5: 212 | HN5: 213 | HO5: 214 | HP5: 215 | HQ5: 216 | HR5: 217 | HS5: 218 | HT5: 219 | HU5: 220 | HV5: 221 | HW5: 222 | HX5: 223 | HY5: 224 | HZ5: 225 | IA5: 226 | IB5: 227 | IC5: 228 | ID5: 229 | IE5: 230 | IF5: 231 | IG5: 232 | IH5: 233 | II5: 234 | IJ5: 235 | IK5: 236 | IL5: 237 | IM5: 238 | IN5: 239 | IO5: 240 | IP5: 241 | IQ5: 242 | IR5: 243 | IS5: 244 | IT5: 245 | IU5: 246 | IV5: 247 | IW5: 248 | IX5: 249 | IY5: 250 | IZ5: 251 | JA5: 252 | JB5: 253 | JC5: 254 | JD5: 255 | JE5: 256 | JF5: 257 | JG5: 258 | JH5: 259 | JI5: 260 | JJ5: 261 | JK5: 262 | JL5: 263 | JM5: 264 | JN5: 265 | JO5: 266 | JP5: 267 | JQ5: 268 | JR5: 269 | JS5: 270 | JT5: 271 | JU5: 272 | JV5: 273 | JW5: 274 | JX5: 275 | JY5: 276 | JZ5: 277 | KA5: 278 | KB5: 279 | KC5: 280 | KD5: 281 | KE5: 282 | KF5: 283 | KG5: 284 | KH5: 285 | KI5: 286 | KJ5: 287 | KK5: 288 | KL5: 289 | KM5: 290 | KN5: 291 | KO5: 292 | KP5: 293 | KQ5: 294 | KR5: 295 | KS5: 296 | KT5: 297 | KU5: 298 | KV5: 299 | KW5: 300 | KX5: 301 | KY5: 302 | KZ5: 303 | LA5: 304 | LB5: 305 | LC5: 306 | LD5: 307 | LE5: 308 | LF5: 309 | LG5: 310 | LH5: 311 | LI5: 312 | LJ5: 313 | LK5: 314 | LL5: 315 | LM5: 316 | LN5: 317 | LO5: 318 | LP5: 319 | LQ5: 320 | LR5: 321 | LS5: 322 | LT5: 323 | LU5: 324 | LV5: 325 | LW5: 326 | LX5: 327 | LY5: 328 | LZ5: 329 | MA5: 330 | MB5: 331 | MC5: 332 | MD5: 333 | ME5: 334 | MF5: 335 | MG5: 336 | MH5: 337 | MI5: 338 | MJ5: 339 | MK5: 340 | ML5: 341 | MM5: 342 | MN5: 343 | MO5: 344 | MP5: 345 | MQ5: 346 | MR5: 347 | MS5: 348 | MT5: 349 | MU5: 350 | MV5: 351 | MW5: 352 | MX5: 353 | MY5: 354 | MZ5: 355 | NA5: 356 | NB5: 357 | NC5: 358 | ND5: 359 | NE5: 360 | NF5: 361 | NG5: 362 | NH5: 363 | NI5: 364 | NJ5: 365 | NK5: 366 | NL5: 367 | NM5: 368 | NN5: 369 | NO5: 370 | NP5: 371 | NQ5: 372 | NR5: 373 | NS5: 374 | NT5: 375 | NU5: 376 | NV5: 377 | NW5: 378 | NX5: 379 | NY5: 380 | NZ5: 381 | OA5: 382 | OB5: 383 | OC5: 384 | OD5: 385 | OE5: 386 | OF5: 387 | OG5: 388 | OH5: 389 | OI5: 390 | OJ5: 391 | OK5: 392 | OL5: 393 | OM5: 394 | ON5: 395 | OO5: 396
J6: =YEAR(J7) -> 2026 | K6: =YEAR(K7) -> 2026 | L6: =YEAR(L7) -> 2026 | M6: =YEAR(M7) -> 2026 | N6: =YEAR(N7) -> 2026 | O6: =YEAR(O7) -> 2026 | P6: =YEAR(P7) -> 2027 | Q6: =YEAR(Q7) -> 2027 | ... OO6: =YEAR(OO7) -> 2059
D7: Costs | E7: Start | F7: End | G7: Months | J7: =Assumptions!C8 -> 46204 | K7: =EOMONTH(J7,1) -> 46265 | L7: =EOMONTH(K7,1) -> 46295 | M7: =EOMONTH(L7,1) -> 46326 | N7: =EOMONTH(M7,1) -> 46356 | O7: =EOMONTH(N7,1) -> 46387 | P7: =EOMONTH(O7,1) -> 46418 | Q7: =EOMONTH(P7,1) -> 46446 | R7: =EOMONTH(Q7,1) -> 46477 | ... OO7: =EOMONTH(ON7,1) -> 58256
B9: DEVELOPMENT PHASE
B11: =Assumptions!B74 -> Acquisition Costs
B12: =Assumptions!B75 -> Building Acquisition | D12: =Assumptions!C75 -> 0 | E12: =Assumptions!$C$8 -> 46204 | F12: =E12 -> 46204 | G12: =((YEAR(F12)-YEAR(E12))*12+MONTH(F12)-MONTH(E12)+1) -> 1 | J12: =-IF(J$7>=$E12,IF(J$7<=$F12,$D12/$G12,0),0) -> 0 | K12: =-IF(K$7>=$E12,IF(K$7<=$F12,$D12/$G12,0),0) -> 0 | L12: =-IF(L$7>=$E12,IF(L$7<=$F12,$D12/$G12,0),0) -> 0 | M12: =-IF(M$7>=$E12,IF(M$7<=$F12,$D12/$G12,0),0) -> 0 | N12: =-IF(N$7>=$E12,IF(N$7<=$F12,$D12/$G12,0),0) -> 0 | O12: =-IF(O$7>=$E12,IF(O$7<=$F12,$D12/$G12,0),0) -> 0 | P12: =-IF(P$7>=$E12,IF(P$7<=$F12,$D12/$G12,0),0) -> 0 | Q12: =-IF(Q$7>=$E12,IF(Q$7<=$F12,$D12/$G12,0),0) -> 0 | ... OO12: =-IF(OO$7>=$E12,IF(OO$7<=$F12,$D12/$G12,0),0) -> 0
B13: =Assumptions!B76 -> Land Acquisition | D13: =Assumptions!C76 -> 1 | E13: =Assumptions!$C$8 -> 46204 | F13: =E13 -> 46204 | G13: =((YEAR(F13)-YEAR(E13))*12+MONTH(F13)-MONTH(E13)+1) -> 1 | J13: =-IF(J$7>=$E13,IF(J$7<=$F13,$D13/$G13,0),0) -> -1 | K13: =-IF(K$7>=$E13,IF(K$7<=$F13,$D13/$G13,0),0) -> 0 | L13: =-IF(L$7>=$E13,IF(L$7<=$F13,$D13/$G13,0),0) -> 0 | M13: =-IF(M$7>=$E13,IF(M$7<=$F13,$D13/$G13,0),0) -> 0 | N13: =-IF(N$7>=$E13,IF(N$7<=$F13,$D13/$G13,0),0) -> 0 | O13: =-IF(O$7>=$E13,IF(O$7<=$F13,$D13/$G13,0),0) -> 0 | P13: =-IF(P$7>=$E13,IF(P$7<=$F13,$D13/$G13,0),0) -> 0 | Q13: =-IF(Q$7>=$E13,IF(Q$7<=$F13,$D13/$G13,0),0) -> 0 | ... OO13: =-IF(OO$7>=$E13,IF(OO$7<=$F13,$D13/$G13,0),0) -> 0
B14: =Assumptions!B77 -> Total Acquisition Costs | D14: =SUM(D12:D13) -> 1 | J14: =SUM(J12:J13) -> -1 | K14: =SUM(K12:K13) -> 0 | L14: =SUM(L12:L13) -> 0 | M14: =SUM(M12:M13) -> 0 | N14: =SUM(N12:N13) -> 0 | O14: =SUM(O12:O13) -> 0 | P14: =SUM(P12:P13) -> 0 | Q14: =SUM(Q12:Q13) -> 0 | ... OO14: =SUM(OO12:OO13) -> 0
B16: Hard Cost & Soft Cost
B17: =Assumptions!B80 -> Contractor Price | D17: =Assumptions!C80 -> 0 | E17: =Assumptions!$C$10 -> 46418 | F17: =EOMONTH(E17,Assumptions!$C$11-1) -> 47118 | G17: =((YEAR(F17)-YEAR(E17))*12+MONTH(F17)-MONTH(E17)+1) -> 24 | J17: =-IF(J$7>=$E17,IF(J$7<=$F17,$D17/$G17,0),0) -> 0 | K17: =-IF(K$7>=$E17,IF(K$7<=$F17,$D17/$G17,0),0) -> 0 | L17: =-IF(L$7>=$E17,IF(L$7<=$F17,$D17/$G17,0),0) -> 0 | M17: =-IF(M$7>=$E17,IF(M$7<=$F17,$D17/$G17,0),0) -> 0 | N17: =-IF(N$7>=$E17,IF(N$7<=$F17,$D17/$G17,0),0) -> 0 | O17: =-IF(O$7>=$E17,IF(O$7<=$F17,$D17/$G17,0),0) -> 0 | P17: =-IF(P$7>=$E17,IF(P$7<=$F17,$D17/$G17,0),0) -> 0 | Q17: =-IF(Q$7>=$E17,IF(Q$7<=$F17,$D17/$G17,0),0) -> 0 | ... OO17: =-IF(OO$7>=$E17,IF(OO$7<=$F17,$D17/$G17,0),0) -> 0
B18: =Assumptions!B81 -> Residential | D18: =Assumptions!C81 -> 164862000 | E18: =Assumptions!$C$10 -> 46418 | F18: =EOMONTH(E18,Assumptions!$C$11-1) -> 47118 | G18: =((YEAR(F18)-YEAR(E18))*12+MONTH(F18)-MONTH(E18)+1) -> 24 | J18: =-IF(J$7>=$E18,IF(J$7<=$F18,$D18/$G18,0),0) -> 0 | K18: =-IF(K$7>=$E18,IF(K$7<=$F18,$D18/$G18,0),0) -> 0 | L18: =-IF(L$7>=$E18,IF(L$7<=$F18,$D18/$G18,0),0) -> 0 | M18: =-IF(M$7>=$E18,IF(M$7<=$F18,$D18/$G18,0),0) -> 0 | N18: =-IF(N$7>=$E18,IF(N$7<=$F18,$D18/$G18,0),0) -> 0 | O18: =-IF(O$7>=$E18,IF(O$7<=$F18,$D18/$G18,0),0) -> 0 | P18: =-IF(P$7>=$E18,IF(P$7<=$F18,$D18/$G18,0),0) -> -6869250 | Q18: =-IF(Q$7>=$E18,IF(Q$7<=$F18,$D18/$G18,0),0) -> -6869250 | ... OO18: =-IF(OO$7>=$E18,IF(OO$7<=$F18,$D18/$G18,0),0) -> 0
B19: =Assumptions!B82 -> Commercial Space | D19: =Assumptions!C82 -> 0 | E19: =Assumptions!$C$10 -> 46418 | F19: =EOMONTH(E19,Assumptions!$C$11-1) -> 47118 | G19: =((YEAR(F19)-YEAR(E19))*12+MONTH(F19)-MONTH(E19)+1) -> 24 | J19: =-IF(J$7>=$E19,IF(J$7<=$F19,$D19/$G19,0),0) -> 0 | K19: =-IF(K$7>=$E19,IF(K$7<=$F19,$D19/$G19,0),0) -> 0 | L19: =-IF(L$7>=$E19,IF(L$7<=$F19,$D19/$G19,0),0) -> 0 | M19: =-IF(M$7>=$E19,IF(M$7<=$F19,$D19/$G19,0),0) -> 0 | N19: =-IF(N$7>=$E19,IF(N$7<=$F19,$D19/$G19,0),0) -> 0 | O19: =-IF(O$7>=$E19,IF(O$7<=$F19,$D19/$G19,0),0) -> 0 | P19: =-IF(P$7>=$E19,IF(P$7<=$F19,$D19/$G19,0),0) -> 0 | Q19: =-IF(Q$7>=$E19,IF(Q$7<=$F19,$D19/$G19,0),0) -> 0 | ... OO19: =-IF(OO$7>=$E19,IF(OO$7<=$F19,$D19/$G19,0),0) -> 0
B20: =Assumptions!B83 -> Community Space | D20: =Assumptions!C83 -> 6300000 | E20: =Assumptions!$C$10 -> 46418 | F20: =EOMONTH(E20,Assumptions!$C$11-1) -> 47118 | G20: =((YEAR(F20)-YEAR(E20))*12+MONTH(F20)-MONTH(E20)+1) -> 24 | J20: =-IF(J$7>=$E20,IF(J$7<=$F20,$D20/$G20,0),0) -> 0 | K20: =-IF(K$7>=$E20,IF(K$7<=$F20,$D20/$G20,0),0) -> 0 | L20: =-IF(L$7>=$E20,IF(L$7<=$F20,$D20/$G20,0),0) -> 0 | M20: =-IF(M$7>=$E20,IF(M$7<=$F20,$D20/$G20,0),0) -> 0 | N20: =-IF(N$7>=$E20,IF(N$7<=$F20,$D20/$G20,0),0) -> 0 | O20: =-IF(O$7>=$E20,IF(O$7<=$F20,$D20/$G20,0),0) -> 0 | P20: =-IF(P$7>=$E20,IF(P$7<=$F20,$D20/$G20,0),0) -> -262500 | Q20: =-IF(Q$7>=$E20,IF(Q$7<=$F20,$D20/$G20,0),0) -> -262500 | ... OO20: =-IF(OO$7>=$E20,IF(OO$7<=$F20,$D20/$G20,0),0) -> 0
B21: =Assumptions!B84 -> Parking | D21: =Assumptions!C84 -> 0 | E21: =Assumptions!$C$10 -> 46418 | F21: =EOMONTH(E21,Assumptions!$C$11-1) -> 47118 | G21: =((YEAR(F21)-YEAR(E21))*12+MONTH(F21)-MONTH(E21)+1) -> 24 | J21: =-IF(J$7>=$E21,IF(J$7<=$F21,$D21/$G21,0),0) -> 0 | K21: =-IF(K$7>=$E21,IF(K$7<=$F21,$D21/$G21,0),0) -> 0 | L21: =-IF(L$7>=$E21,IF(L$7<=$F21,$D21/$G21,0),0) -> 0 | M21: =-IF(M$7>=$E21,IF(M$7<=$F21,$D21/$G21,0),0) -> 0 | N21: =-IF(N$7>=$E21,IF(N$7<=$F21,$D21/$G21,0),0) -> 0 | O21: =-IF(O$7>=$E21,IF(O$7<=$F21,$D21/$G21,0),0) -> 0 | P21: =-IF(P$7>=$E21,IF(P$7<=$F21,$D21/$G21,0),0) -> 0 | Q21: =-IF(Q$7>=$E21,IF(Q$7<=$F21,$D21/$G21,0),0) -> 0 | ... OO21: =-IF(OO$7>=$E21,IF(OO$7<=$F21,$D21/$G21,0),0) -> 0
B22: =Assumptions!B85 -> Developer Fee | D22: =Assumptions!C85 -> 878000 | E22: =Assumptions!$C$10 -> 46418 | F22: =EOMONTH(E22,Assumptions!$C$11-1) -> 47118 | G22: =((YEAR(F22)-YEAR(E22))*12+MONTH(F22)-MONTH(E22)+1) -> 24 | J22: =-IF(J$7>=$E22,IF(J$7<=$F22,$D22/$G22,0),0) -> 0 | K22: =-IF(K$7>=$E22,IF(K$7<=$F22,$D22/$G22,0),0) -> 0 | L22: =-IF(L$7>=$E22,IF(L$7<=$F22,$D22/$G22,0),0) -> 0 | M22: =-IF(M$7>=$E22,IF(M$7<=$F22,$D22/$G22,0),0) -> 0 | N22: =-IF(N$7>=$E22,IF(N$7<=$F22,$D22/$G22,0),0) -> 0 | O22: =-IF(O$7>=$E22,IF(O$7<=$F22,$D22/$G22,0),0) -> 0 | P22: =-IF(P$7>=$E22,IF(P$7<=$F22,$D22/$G22,0),0) -> -36583.333 | Q22: =-IF(Q$7>=$E22,IF(Q$7<=$F22,$D22/$G22,0),0) -> -36583.333 | ... OO22: =-IF(OO$7>=$E22,IF(OO$7<=$F22,$D22/$G22,0),0) -> 0
B23: =Assumptions!B86 -> Contingent Hard Costs | D23: =Assumptions!C86 -> 0 | E23: =Assumptions!$C$10 -> 46418 | F23: =EOMONTH(E23,Assumptions!$C$11-1) -> 47118 | G23: =((YEAR(F23)-YEAR(E23))*12+MONTH(F23)-MONTH(E23)+1) -> 24 | J23: =-IF(J$7>=$E23,IF(J$7<=$F23,$D23/$G23,0),0) -> 0 | K23: =-IF(K$7>=$E23,IF(K$7<=$F23,$D23/$G23,0),0) -> 0 | L23: =-IF(L$7>=$E23,IF(L$7<=$F23,$D23/$G23,0),0) -> 0 | M23: =-IF(M$7>=$E23,IF(M$7<=$F23,$D23/$G23,0),0) -> 0 | N23: =-IF(N$7>=$E23,IF(N$7<=$F23,$D23/$G23,0),0) -> 0 | O23: =-IF(O$7>=$E23,IF(O$7<=$F23,$D23/$G23,0),0) -> 0 | P23: =-IF(P$7>=$E23,IF(P$7<=$F23,$D23/$G23,0),0) -> 0 | Q23: =-IF(Q$7>=$E23,IF(Q$7<=$F23,$D23/$G23,0),0) -> 0 | ... OO23: =-IF(OO$7>=$E23,IF(OO$7<=$F23,$D23/$G23,0),0) -> 0
B24: =Assumptions!B87 -> General Conditions | D24: =Assumptions!C87 -> 10269720 | E24: =Assumptions!$C$10 -> 46418 | F24: =EOMONTH(E24,Assumptions!$C$11-1) -> 47118 | G24: =((YEAR(F24)-YEAR(E24))*12+MONTH(F24)-MONTH(E24)+1) -> 24 | J24: =-IF(J$7>=$E24,IF(J$7<=$F24,$D24/$G24,0),0) -> 0 | K24: =-IF(K$7>=$E24,IF(K$7<=$F24,$D24/$G24,0),0) -> 0 | L24: =-IF(L$7>=$E24,IF(L$7<=$F24,$D24/$G24,0),0) -> 0 | M24: =-IF(M$7>=$E24,IF(M$7<=$F24,$D24/$G24,0),0) -> 0 | N24: =-IF(N$7>=$E24,IF(N$7<=$F24,$D24/$G24,0),0) -> 0 | O24: =-IF(O$7>=$E24,IF(O$7<=$F24,$D24/$G24,0),0) -> 0 | P24: =-IF(P$7>=$E24,IF(P$7<=$F24,$D24/$G24,0),0) -> -427905 | Q24: =-IF(Q$7>=$E24,IF(Q$7<=$F24,$D24/$G24,0),0) -> -427905 | ... OO24: =-IF(OO$7>=$E24,IF(OO$7<=$F24,$D24/$G24,0),0) -> 0
B25: =Assumptions!B88 -> Overhead | D25: =Assumptions!C88 -> 3423240 | E25: =Assumptions!$C$10 -> 46418 | F25: =EOMONTH(E25,Assumptions!$C$11-1) -> 47118 | G25: =((YEAR(F25)-YEAR(E25))*12+MONTH(F25)-MONTH(E25)+1) -> 24 | J25: =-IF(J$7>=$E25,IF(J$7<=$F25,$D25/$G25,0),0) -> 0 | K25: =-IF(K$7>=$E25,IF(K$7<=$F25,$D25/$G25,0),0) -> 0 | L25: =-IF(L$7>=$E25,IF(L$7<=$F25,$D25/$G25,0),0) -> 0 | M25: =-IF(M$7>=$E25,IF(M$7<=$F25,$D25/$G25,0),0) -> 0 | N25: =-IF(N$7>=$E25,IF(N$7<=$F25,$D25/$G25,0),0) -> 0 | O25: =-IF(O$7>=$E25,IF(O$7<=$F25,$D25/$G25,0),0) -> 0 | P25: =-IF(P$7>=$E25,IF(P$7<=$F25,$D25/$G25,0),0) -> -142635 | Q25: =-IF(Q$7>=$E25,IF(Q$7<=$F25,$D25/$G25,0),0) -> -142635 | ... OO25: =-IF(OO$7>=$E25,IF(OO$7<=$F25,$D25/$G25,0),0) -> 0
B26: =Assumptions!B89 -> Contractor Profit | D26: =Assumptions!C89 -> 10269720 | E26: =Assumptions!$C$10 -> 46418 | F26: =EOMONTH(E26,Assumptions!$C$11-1) -> 47118 | G26: =((YEAR(F26)-YEAR(E26))*12+MONTH(F26)-MONTH(E26)+1) -> 24 | J26: =-IF(J$7>=$E26,IF(J$7<=$F26,$D26/$G26,0),0) -> 0 | K26: =-IF(K$7>=$E26,IF(K$7<=$F26,$D26/$G26,0),0) -> 0 | L26: =-IF(L$7>=$E26,IF(L$7<=$F26,$D26/$G26,0),0) -> 0 | M26: =-IF(M$7>=$E26,IF(M$7<=$F26,$D26/$G26,0),0) -> 0 | N26: =-IF(N$7>=$E26,IF(N$7<=$F26,$D26/$G26,0),0) -> 0 | O26: =-IF(O$7>=$E26,IF(O$7<=$F26,$D26/$G26,0),0) -> 0 | P26: =-IF(P$7>=$E26,IF(P$7<=$F26,$D26/$G26,0),0) -> -427905 | Q26: =-IF(Q$7>=$E26,IF(Q$7<=$F26,$D26/$G26,0),0) -> -427905 | ... OO26: =-IF(OO$7>=$E26,IF(OO$7<=$F26,$D26/$G26,0),0) -> 0
B27: =Assumptions!B90 -> Bond Premium | D27: =Assumptions!C90 -> 1711620 | E27: =Assumptions!$C$10 -> 46418 | F27: =EOMONTH(E27,Assumptions!$C$11-1) -> 47118 | G27: =((YEAR(F27)-YEAR(E27))*12+MONTH(F27)-MONTH(E27)+1) -> 24 | J27: =-IF(J$7>=$E27,IF(J$7<=$F27,$D27/$G27,0),0) -> 0 | K27: =-IF(K$7>=$E27,IF(K$7<=$F27,$D27/$G27,0),0) -> 0 | L27: =-IF(L$7>=$E27,IF(L$7<=$F27,$D27/$G27,0),0) -> 0 | M27: =-IF(M$7>=$E27,IF(M$7<=$F27,$D27/$G27,0),0) -> 0 | N27: =-IF(N$7>=$E27,IF(N$7<=$F27,$D27/$G27,0),0) -> 0 | O27: =-IF(O$7>=$E27,IF(O$7<=$F27,$D27/$G27,0),0) -> 0 | P27: =-IF(P$7>=$E27,IF(P$7<=$F27,$D27/$G27,0),0) -> -71317.5 | Q27: =-IF(Q$7>=$E27,IF(Q$7<=$F27,$D27/$G27,0),0) -> -71317.5 | ... OO27: =-IF(OO$7>=$E27,IF(OO$7<=$F27,$D27/$G27,0),0) -> 0
B28: =Assumptions!B91 -> Contingency | D28: =Assumptions!C91 -> 8558100 | E28: =Assumptions!$C$10 -> 46418 | F28: =EOMONTH(E28,Assumptions!$C$11-1) -> 47118 | G28: =((YEAR(F28)-YEAR(E28))*12+MONTH(F28)-MONTH(E28)+1) -> 24 | J28: =-IF(J$7>=$E28,IF(J$7<=$F28,$D28/$G28,0),0) -> 0 | K28: =-IF(K$7>=$E28,IF(K$7<=$F28,$D28/$G28,0),0) -> 0 | L28: =-IF(L$7>=$E28,IF(L$7<=$F28,$D28/$G28,0),0) -> 0 | M28: =-IF(M$7>=$E28,IF(M$7<=$F28,$D28/$G28,0),0) -> 0 | N28: =-IF(N$7>=$E28,IF(N$7<=$F28,$D28/$G28,0),0) -> 0 | O28: =-IF(O$7>=$E28,IF(O$7<=$F28,$D28/$G28,0),0) -> 0 | P28: =-IF(P$7>=$E28,IF(P$7<=$F28,$D28/$G28,0),0) -> -356587.5 | Q28: =-IF(Q$7>=$E28,IF(Q$7<=$F28,$D28/$G28,0),0) -> -356587.5 | ... OO28: =-IF(OO$7>=$E28,IF(OO$7<=$F28,$D28/$G28,0),0) -> 0
B30: =Assumptions!B95 -> Accounting & Cost Certification | D30: =Assumptions!C95 -> 30000 | E30: =Assumptions!$C$8 -> 46204 | F30: =EOMONTH(E30,Assumptions!$C$9-1) -> 46387 | G30: =((YEAR(F30)-YEAR(E30))*12+MONTH(F30)-MONTH(E30)+1) -> 6 | J30: =-IF(J$7>=$E30,IF(J$7<=$F30,$D30/$G30,0),0) -> -5000 | K30: =-IF(K$7>=$E30,IF(K$7<=$F30,$D30/$G30,0),0) -> -5000 | L30: =-IF(L$7>=$E30,IF(L$7<=$F30,$D30/$G30,0),0) -> -5000 | M30: =-IF(M$7>=$E30,IF(M$7<=$F30,$D30/$G30,0),0) -> -5000 | N30: =-IF(N$7>=$E30,IF(N$7<=$F30,$D30/$G30,0),0) -> -5000 | O30: =-IF(O$7>=$E30,IF(O$7<=$F30,$D30/$G30,0),0) -> -5000 | P30: =-IF(P$7>=$E30,IF(P$7<=$F30,$D30/$G30,0),0) -> 0 | Q30: =-IF(Q$7>=$E30,IF(Q$7<=$F30,$D30/$G30,0),0) -> 0 | ... OO30: =-IF(OO$7>=$E30,IF(OO$7<=$F30,$D30/$G30,0),0) -> 0
B31: =Assumptions!B96 -> Appraisal | D31: =Assumptions!C96 -> 10000 | E31: =Assumptions!$C$8 -> 46204 | F31: =EOMONTH(E31,Assumptions!$C$9-1) -> 46387 | G31: =((YEAR(F31)-YEAR(E31))*12+MONTH(F31)-MONTH(E31)+1) -> 6 | J31: =-IF(J$7>=$E31,IF(J$7<=$F31,$D31/$G31,0),0) -> -1666.6667 | K31: =-IF(K$7>=$E31,IF(K$7<=$F31,$D31/$G31,0),0) -> -1666.6667 | L31: =-IF(L$7>=$E31,IF(L$7<=$F31,$D31/$G31,0),0) -> -1666.6667 | M31: =-IF(M$7>=$E31,IF(M$7<=$F31,$D31/$G31,0),0) -> -1666.6667 | N31: =-IF(N$7>=$E31,IF(N$7<=$F31,$D31/$G31,0),0) -> -1666.6667 | O31: =-IF(O$7>=$E31,IF(O$7<=$F31,$D31/$G31,0),0) -> -1666.6667 | P31: =-IF(P$7>=$E31,IF(P$7<=$F31,$D31/$G31,0),0) -> 0 | Q31: =-IF(Q$7>=$E31,IF(Q$7<=$F31,$D31/$G31,0),0) -> 0 | ... OO31: =-IF(OO$7>=$E31,IF(OO$7<=$F31,$D31/$G31,0),0) -> 0
B32: =Assumptions!B97 -> Architect / Engineer | D32: =Assumptions!C97 -> 2400000 | E32: =Assumptions!$C$8 -> 46204 | F32: =EOMONTH(E32,Assumptions!$C$9-1) -> 46387 | G32: =((YEAR(F32)-YEAR(E32))*12+MONTH(F32)-MONTH(E32)+1) -> 6 | J32: =-IF(J$7>=$E32,IF(J$7<=$F32,$D32/$G32,0),0) -> -400000 | K32: =-IF(K$7>=$E32,IF(K$7<=$F32,$D32/$G32,0),0) -> -400000 | L32: =-IF(L$7>=$E32,IF(L$7<=$F32,$D32/$G32,0),0) -> -400000 | M32: =-IF(M$7>=$E32,IF(M$7<=$F32,$D32/$G32,0),0) -> -400000 | N32: =-IF(N$7>=$E32,IF(N$7<=$F32,$D32/$G32,0),0) -> -400000 | O32: =-IF(O$7>=$E32,IF(O$7<=$F32,$D32/$G32,0),0) -> -400000 | P32: =-IF(P$7>=$E32,IF(P$7<=$F32,$D32/$G32,0),0) -> 0 | Q32: =-IF(Q$7>=$E32,IF(Q$7<=$F32,$D32/$G32,0),0) -> 0 | ... OO32: =-IF(OO$7>=$E32,IF(OO$7<=$F32,$D32/$G32,0),0) -> 0
B33: =Assumptions!B98 -> Permits and Expediting | D33: =Assumptions!C98 -> 95000 | E33: =Assumptions!$C$8 -> 46204 | F33: =EOMONTH(E33,Assumptions!$C$9-1) -> 46387 | G33: =((YEAR(F33)-YEAR(E33))*12+MONTH(F33)-MONTH(E33)+1) -> 6 | J33: =-IF(J$7>=$E33,IF(J$7<=$F33,$D33/$G33,0),0) -> -15833.333 | K33: =-IF(K$7>=$E33,IF(K$7<=$F33,$D33/$G33,0),0) -> -15833.333 | L33: =-IF(L$7>=$E33,IF(L$7<=$F33,$D33/$G33,0),0) -> -15833.333 | M33: =-IF(M$7>=$E33,IF(M$7<=$F33,$D33/$G33,0),0) -> -15833.333 | N33: =-IF(N$7>=$E33,IF(N$7<=$F33,$D33/$G33,0),0) -> -15833.333 | O33: =-IF(O$7>=$E33,IF(O$7<=$F33,$D33/$G33,0),0) -> -15833.333 | P33: =-IF(P$7>=$E33,IF(P$7<=$F33,$D33/$G33,0),0) -> 0 | Q33: =-IF(Q$7>=$E33,IF(Q$7<=$F33,$D33/$G33,0),0) -> 0 | ... OO33: =-IF(OO$7>=$E33,IF(OO$7<=$F33,$D33/$G33,0),0) -> 0
B34: =Assumptions!B99 -> Environmental Phase I & II | D34: =Assumptions!C99 -> 35000 | E34: =Assumptions!$C$8 -> 46204 | F34: =EOMONTH(E34,Assumptions!$C$9-1) -> 46387 | G34: =((YEAR(F34)-YEAR(E34))*12+MONTH(F34)-MONTH(E34)+1) -> 6 | J34: =-IF(J$7>=$E34,IF(J$7<=$F34,$D34/$G34,0),0) -> -5833.3333 | K34: =-IF(K$7>=$E34,IF(K$7<=$F34,$D34/$G34,0),0) -> -5833.3333 | L34: =-IF(L$7>=$E34,IF(L$7<=$F34,$D34/$G34,0),0) -> -5833.3333 | M34: =-IF(M$7>=$E34,IF(M$7<=$F34,$D34/$G34,0),0) -> -5833.3333 | N34: =-IF(N$7>=$E34,IF(N$7<=$F34,$D34/$G34,0),0) -> -5833.3333 | O34: =-IF(O$7>=$E34,IF(O$7<=$F34,$D34/$G34,0),0) -> -5833.3333 | P34: =-IF(P$7>=$E34,IF(P$7<=$F34,$D34/$G34,0),0) -> 0 | Q34: =-IF(Q$7>=$E34,IF(Q$7<=$F34,$D34/$G34,0),0) -> 0 | ... OO34: =-IF(OO$7>=$E34,IF(OO$7<=$F34,$D34/$G34,0),0) -> 0
B35: =Assumptions!B100 -> Geotechnical | D35: =Assumptions!C100 -> 0 | E35: =Assumptions!$C$8 -> 46204 | F35: =EOMONTH(E35,Assumptions!$C$9-1) -> 46387 | G35: =((YEAR(F35)-YEAR(E35))*12+MONTH(F35)-MONTH(E35)+1) -> 6 | J35: =-IF(J$7>=$E35,IF(J$7<=$F35,$D35/$G35,0),0) -> 0 | K35: =-IF(K$7>=$E35,IF(K$7<=$F35,$D35/$G35,0),0) -> 0 | L35: =-IF(L$7>=$E35,IF(L$7<=$F35,$D35/$G35,0),0) -> 0 | M35: =-IF(M$7>=$E35,IF(M$7<=$F35,$D35/$G35,0),0) -> 0 | N35: =-IF(N$7>=$E35,IF(N$7<=$F35,$D35/$G35,0),0) -> 0 | O35: =-IF(O$7>=$E35,IF(O$7<=$F35,$D35/$G35,0),0) -> 0 | P35: =-IF(P$7>=$E35,IF(P$7<=$F35,$D35/$G35,0),0) -> 0 | Q35: =-IF(Q$7>=$E35,IF(Q$7<=$F35,$D35/$G35,0),0) -> 0 | ... OO35: =-IF(OO$7>=$E35,IF(OO$7<=$F35,$D35/$G35,0),0) -> 0
B36: =Assumptions!B101 -> Insurance | D36: =Assumptions!C101 -> 1000000 | E36: =Assumptions!$C$8 -> 46204 | F36: =EOMONTH(E36,Assumptions!$C$9-1) -> 46387 | G36: =((YEAR(F36)-YEAR(E36))*12+MONTH(F36)-MONTH(E36)+1) -> 6 | J36: =-IF(J$7>=$E36,IF(J$7<=$F36,$D36/$G36,0),0) -> -166666.67 | K36: =-IF(K$7>=$E36,IF(K$7<=$F36,$D36/$G36,0),0) -> -166666.67 | L36: =-IF(L$7>=$E36,IF(L$7<=$F36,$D36/$G36,0),0) -> -166666.67 | M36: =-IF(M$7>=$E36,IF(M$7<=$F36,$D36/$G36,0),0) -> -166666.67 | N36: =-IF(N$7>=$E36,IF(N$7<=$F36,$D36/$G36,0),0) -> -166666.67 | O36: =-IF(O$7>=$E36,IF(O$7<=$F36,$D36/$G36,0),0) -> -166666.67 | P36: =-IF(P$7>=$E36,IF(P$7<=$F36,$D36/$G36,0),0) -> 0 | Q36: =-IF(Q$7>=$E36,IF(Q$7<=$F36,$D36/$G36,0),0) -> 0 | ... OO36: =-IF(OO$7>=$E36,IF(OO$7<=$F36,$D36/$G36,0),0) -> 0
B37: =Assumptions!B102 -> Market Study | D37: =Assumptions!C102 -> 7500 | E37: =Assumptions!$C$8 -> 46204 | F37: =EOMONTH(E37,Assumptions!$C$9-1) -> 46387 | G37: =((YEAR(F37)-YEAR(E37))*12+MONTH(F37)-MONTH(E37)+1) -> 6 | J37: =-IF(J$7>=$E37,IF(J$7<=$F37,$D37/$G37,0),0) -> -1250 | K37: =-IF(K$7>=$E37,IF(K$7<=$F37,$D37/$G37,0),0) -> -1250 | L37: =-IF(L$7>=$E37,IF(L$7<=$F37,$D37/$G37,0),0) -> -1250 | M37: =-IF(M$7>=$E37,IF(M$7<=$F37,$D37/$G37,0),0) -> -1250 | N37: =-IF(N$7>=$E37,IF(N$7<=$F37,$D37/$G37,0),0) -> -1250 | O37: =-IF(O$7>=$E37,IF(O$7<=$F37,$D37/$G37,0),0) -> -1250 | P37: =-IF(P$7>=$E37,IF(P$7<=$F37,$D37/$G37,0),0) -> 0 | Q37: =-IF(Q$7>=$E37,IF(Q$7<=$F37,$D37/$G37,0),0) -> 0 | ... OO37: =-IF(OO$7>=$E37,IF(OO$7<=$F37,$D37/$G37,0),0) -> 0
B38: =Assumptions!B103 -> Marketing | D38: =Assumptions!C103 -> 329000 | E38: =Assumptions!$C$8 -> 46204 | F38: =EOMONTH(E38,Assumptions!$C$9-1) -> 46387 | G38: =((YEAR(F38)-YEAR(E38))*12+MONTH(F38)-MONTH(E38)+1) -> 6 | J38: =-IF(J$7>=$E38,IF(J$7<=$F38,$D38/$G38,0),0) -> -54833.333 | K38: =-IF(K$7>=$E38,IF(K$7<=$F38,$D38/$G38,0),0) -> -54833.333 | L38: =-IF(L$7>=$E38,IF(L$7<=$F38,$D38/$G38,0),0) -> -54833.333 | M38: =-IF(M$7>=$E38,IF(M$7<=$F38,$D38/$G38,0),0) -> -54833.333 | N38: =-IF(N$7>=$E38,IF(N$7<=$F38,$D38/$G38,0),0) -> -54833.333 | O38: =-IF(O$7>=$E38,IF(O$7<=$F38,$D38/$G38,0),0) -> -54833.333 | P38: =-IF(P$7>=$E38,IF(P$7<=$F38,$D38/$G38,0),0) -> 0 | Q38: =-IF(Q$7>=$E38,IF(Q$7<=$F38,$D38/$G38,0),0) -> 0 | ... OO38: =-IF(OO$7>=$E38,IF(OO$7<=$F38,$D38/$G38,0),0) -> 0
B39: =Assumptions!B104 -> Permits / Fees | D39: =Assumptions!C104 -> 75000 | E39: =Assumptions!$C$8 -> 46204 | F39: =EOMONTH(E39,Assumptions!$C$9-1) -> 46387 | G39: =((YEAR(F39)-YEAR(E39))*12+MONTH(F39)-MONTH(E39)+1) -> 6 | J39: =-IF(J$7>=$E39,IF(J$7<=$F39,$D39/$G39,0),0) -> -12500 | K39: =-IF(K$7>=$E39,IF(K$7<=$F39,$D39/$G39,0),0) -> -12500 | L39: =-IF(L$7>=$E39,IF(L$7<=$F39,$D39/$G39,0),0) -> -12500 | M39: =-IF(M$7>=$E39,IF(M$7<=$F39,$D39/$G39,0),0) -> -12500 | N39: =-IF(N$7>=$E39,IF(N$7<=$F39,$D39/$G39,0),0) -> -12500 | O39: =-IF(O$7>=$E39,IF(O$7<=$F39,$D39/$G39,0),0) -> -12500 | P39: =-IF(P$7>=$E39,IF(P$7<=$F39,$D39/$G39,0),0) -> 0 | Q39: =-IF(Q$7>=$E39,IF(Q$7<=$F39,$D39/$G39,0),0) -> 0 | ... OO39: =-IF(OO$7>=$E39,IF(OO$7<=$F39,$D39/$G39,0),0) -> 0
B40: =Assumptions!B105 -> Survey | D40: =Assumptions!C105 -> 7500 | E40: =Assumptions!$C$8 -> 46204 | F40: =EOMONTH(E40,Assumptions!$C$9-1) -> 46387 | G40: =((YEAR(F40)-YEAR(E40))*12+MONTH(F40)-MONTH(E40)+1) -> 6 | J40: =-IF(J$7>=$E40,IF(J$7<=$F40,$D40/$G40,0),0) -> -1250 | K40: =-IF(K$7>=$E40,IF(K$7<=$F40,$D40/$G40,0),0) -> -1250 | L40: =-IF(L$7>=$E40,IF(L$7<=$F40,$D40/$G40,0),0) -> -1250 | M40: =-IF(M$7>=$E40,IF(M$7<=$F40,$D40/$G40,0),0) -> -1250 | N40: =-IF(N$7>=$E40,IF(N$7<=$F40,$D40/$G40,0),0) -> -1250 | O40: =-IF(O$7>=$E40,IF(O$7<=$F40,$D40/$G40,0),0) -> -1250 | P40: =-IF(P$7>=$E40,IF(P$7<=$F40,$D40/$G40,0),0) -> 0 | Q40: =-IF(Q$7>=$E40,IF(Q$7<=$F40,$D40/$G40,0),0) -> 0 | ... OO40: =-IF(OO$7>=$E40,IF(OO$7<=$F40,$D40/$G40,0),0) -> 0
B41: =Assumptions!B106 -> Borings | D41: =Assumptions!C106 -> 125000 | E41: =Assumptions!$C$8 -> 46204 | F41: =EOMONTH(E41,Assumptions!$C$9-1) -> 46387 | G41: =((YEAR(F41)-YEAR(E41))*12+MONTH(F41)-MONTH(E41)+1) -> 6 | J41: =-IF(J$7>=$E41,IF(J$7<=$F41,$D41/$G41,0),0) -> -20833.333 | K41: =-IF(K$7>=$E41,IF(K$7<=$F41,$D41/$G41,0),0) -> -20833.333 | L41: =-IF(L$7>=$E41,IF(L$7<=$F41,$D41/$G41,0),0) -> -20833.333 | M41: =-IF(M$7>=$E41,IF(M$7<=$F41,$D41/$G41,0),0) -> -20833.333 | N41: =-IF(N$7>=$E41,IF(N$7<=$F41,$D41/$G41,0),0) -> -20833.333 | O41: =-IF(O$7>=$E41,IF(O$7<=$F41,$D41/$G41,0),0) -> -20833.333 | P41: =-IF(P$7>=$E41,IF(P$7<=$F41,$D41/$G41,0),0) -> 0 | Q41: =-IF(Q$7>=$E41,IF(Q$7<=$F41,$D41/$G41,0),0) -> 0 | ... OO41: =-IF(OO$7>=$E41,IF(OO$7<=$F41,$D41/$G41,0),0) -> 0
... B44: =Assumptions!B109 -> Soft Cost Contingency | D44: =Assumptions!C109 -> 1885875.5 | E44: =Assumptions!$C$8 -> 46204 | F44: =EOMONTH(E44,Assumptions!$C$9-1) -> 46387 | G44: =((YEAR(F44)-YEAR(E44))*12+MONTH(F44)-MONTH(E44)+1) -> 6 | J44: =-IF(J$7>=$E44,IF(J$7<=$F44,$D44/$G44,0),0) -> -314312.58 | K44: =-IF(K$7>=$E44,IF(K$7<=$F44,$D44/$G44,0),0) -> -314312.58 | L44: =-IF(L$7>=$E44,IF(L$7<=$F44,$D44/$G44,0),0) -> -314312.58 | M44: =-IF(M$7>=$E44,IF(M$7<=$F44,$D44/$G44,0),0) -> -314312.58 | N44: =-IF(N$7>=$E44,IF(N$7<=$F44,$D44/$G44,0),0) -> -314312.58 | O44: =-IF(O$7>=$E44,IF(O$7<=$F44,$D44/$G44,0),0) -> -314312.58 | P44: =-IF(P$7>=$E44,IF(P$7<=$F44,$D44/$G44,0),0) -> 0 | Q44: =-IF(Q$7>=$E44,IF(Q$7<=$F44,$D44/$G44,0),0) -> 0 | ... OO44: =-IF(OO$7>=$E44,IF(OO$7<=$F44,$D44/$G44,0),0) -> 0
B46: =Assumptions!B113 -> Borrower Legal | D46: =Assumptions!C113 -> 375000 | E46: =Assumptions!$C$8 -> 46204 | F46: =EOMONTH(E46,Assumptions!$C$9-1) -> 46387 | G46: =((YEAR(F46)-YEAR(E46))*12+MONTH(F46)-MONTH(E46)+1) -> 6 | J46: =-IF(J$7>=$E46,IF(J$7<=$F46,$D46/$G46,0),0) -> -62500 | K46: =-IF(K$7>=$E46,IF(K$7<=$F46,$D46/$G46,0),0) -> -62500 | L46: =-IF(L$7>=$E46,IF(L$7<=$F46,$D46/$G46,0),0) -> -62500 | M46: =-IF(M$7>=$E46,IF(M$7<=$F46,$D46/$G46,0),0) -> -62500 | N46: =-IF(N$7>=$E46,IF(N$7<=$F46,$D46/$G46,0),0) -> -62500 | O46: =-IF(O$7>=$E46,IF(O$7<=$F46,$D46/$G46,0),0) -> -62500 | P46: =-IF(P$7>=$E46,IF(P$7<=$F46,$D46/$G46,0),0) -> 0 | Q46: =-IF(Q$7>=$E46,IF(Q$7<=$F46,$D46/$G46,0),0) -> 0 | ... OO46: =-IF(OO$7>=$E46,IF(OO$7<=$F46,$D46/$G46,0),0) -> 0
B47: =Assumptions!B114 -> Bank Legal | D47: =Assumptions!C114 -> 40000 | E47: =Assumptions!$C$8 -> 46204 | F47: =EOMONTH(E47,Assumptions!$C$9-1) -> 46387 | G47: =((YEAR(F47)-YEAR(E47))*12+MONTH(F47)-MONTH(E47)+1) -> 6 | J47: =-IF(J$7>=$E47,IF(J$7<=$F47,$D47/$G47,0),0) -> -6666.6667 | K47: =-IF(K$7>=$E47,IF(K$7<=$F47,$D47/$G47,0),0) -> -6666.6667 | L47: =-IF(L$7>=$E47,IF(L$7<=$F47,$D47/$G47,0),0) -> -6666.6667 | M47: =-IF(M$7>=$E47,IF(M$7<=$F47,$D47/$G47,0),0) -> -6666.6667 | N47: =-IF(N$7>=$E47,IF(N$7<=$F47,$D47/$G47,0),0) -> -6666.6667 | O47: =-IF(O$7>=$E47,IF(O$7<=$F47,$D47/$G47,0),0) -> -6666.6667 | P47: =-IF(P$7>=$E47,IF(P$7<=$F47,$D47/$G47,0),0) -> 0 | Q47: =-IF(Q$7>=$E47,IF(Q$7<=$F47,$D47/$G47,0),0) -> 0 | ... OO47: =-IF(OO$7>=$E47,IF(OO$7<=$F47,$D47/$G47,0),0) -> 0
B48: =Assumptions!B115 -> Tax Credit Certification | D48: =Assumptions!C115 -> 421496 | E48: =Assumptions!$C$8 -> 46204 | F48: =EOMONTH(E48,Assumptions!$C$9-1) -> 46387 | G48: =((YEAR(F48)-YEAR(E48))*12+MONTH(F48)-MONTH(E48)+1) -> 6 | J48: =-IF(J$7>=$E48,IF(J$7<=$F48,$D48/$G48,0),0) -> -70249.333 | K48: =-IF(K$7>=$E48,IF(K$7<=$F48,$D48/$G48,0),0) -> -70249.333 | L48: =-IF(L$7>=$E48,IF(L$7<=$F48,$D48/$G48,0),0) -> -70249.333 | M48: =-IF(M$7>=$E48,IF(M$7<=$F48,$D48/$G48,0),0) -> -70249.333 | N48: =-IF(N$7>=$E48,IF(N$7<=$F48,$D48/$G48,0),0) -> -70249.333 | O48: =-IF(O$7>=$E48,IF(O$7<=$F48,$D48/$G48,0),0) -> -70249.333 | P48: =-IF(P$7>=$E48,IF(P$7<=$F48,$D48/$G48,0),0) -> 0 | Q48: =-IF(Q$7>=$E48,IF(Q$7<=$F48,$D48/$G48,0),0) -> 0 | ... OO48: =-IF(OO$7>=$E48,IF(OO$7<=$F48,$D48/$G48,0),0) -> 0
B50: Total Hard & Soft Cost | D50: =SUM(D17:D48) -> 2.1397548e+08 | J50: =SUM(J17:J48) -> -1283846.6 | K50: =SUM(K17:K48) -> -1283846.6 | L50: =SUM(L17:L48) -> -1283846.6 | M50: =SUM(M17:M48) -> -1283846.6 | N50: =SUM(N17:N48) -> -1283846.6 | O50: =SUM(O17:O48) -> -1283846.6 | P50: =SUM(P17:P48) -> -8594683.3 | Q50: =SUM(Q17:Q48) -> -8594683.3 | ... OO50: =SUM(OO17:OO48) -> 0
...

Sheet Development CF
B2: Development CASH FLOW
B3: ALL figures are in USD
B5: Development amount coverage | D5: loan draws % | E5: LIHTC + def. developer fee | F5: Amt after LIHTC
B6: =Assumptions!C150 -> 2.4878145e+08 | D6: =Amortization!H8 -> 0.82029895 | E6: =100%-D6 -> 0.17970105 | F6: ='Sources and Uses'!C8 -> 10635591
D7: =B6*D6 -> 2.0407516e+08 | E7: =B6*E6 -> 44706287 | F7: =E7-F6 -> 34070696
E10: 1 | F10: 2 | G10: 3 | H10: 4 | I10: 5 | J10: 6 | K10: 7 | L10: 8 | M10: 9 | N10: 10 | O10: 11 | P10: 12 | Q10: 13 | R10: 14 | S10: 15 | T10: 16 | U10: 17 | V10: 18 | W10: 19 | X10: 20 | Y10: 21 | Z10: 22 | AA10: 23 | AB10: 24 | AC10: 25 | AD10: 26 | AE10: 27 | AF10: 28 | AG10: 29 | AH10: 30
E11: =YEAR(E12) -> 2027 | F11: =YEAR(F12) -> 2027 | G11: =YEAR(G12) -> 2027 | H11: =YEAR(H12) -> 2027 | I11: =YEAR(I12) -> 2027 | J11: =YEAR(J12) -> 2027 | K11: =YEAR(K12) -> 2027 | L11: =YEAR(L12) -> 2027 | ... AH11: =YEAR(AH12) -> 2029
E12: =Assumptions!C10 -> 46418 | F12: =EOMONTH(E12,1) -> 46446 | G12: =EOMONTH(F12,1) -> 46477 | H12: =EOMONTH(G12,1) -> 46507 | I12: =EOMONTH(H12,1) -> 46538 | J12: =EOMONTH(I12,1) -> 46568 | K12: =EOMONTH(J12,1) -> 46599 | L12: =EOMONTH(K12,1) -> 46630 | M12: =EOMONTH(L12,1) -> 46660 | ... AH12: =EOMONTH(AG12,1) -> 47299
B14: Inflow
B15: Rental Income | D15: =-SUM(E15:AH15) -> 0 | E15: =IF(E12>=Assumptions!$C$13,'Rental CF'!F$29,0) -> 0 | F15: =IF(F12>=Assumptions!$C$13,'Rental CF'!G$29,0) -> 0 | G15: =IF(G12>=Assumptions!$C$13,'Rental CF'!H$29,0) -> 0 | H15: =IF(H12>=Assumptions!$C$13,'Rental CF'!I$29,0) -> 0 | I15: =IF(I12>=Assumptions!$C$13,'Rental CF'!J$29,0) -> 0 | J15: =IF(J12>=Assumptions!$C$13,'Rental CF'!K$29,0) -> 0 | K15: =IF(K12>=Assumptions!$C$13,'Rental CF'!L$29,0) -> 0 | L15: =IF(L12>=Assumptions!$C$13,'Rental CF'!M$29,0) -> 0 | ... AH15: =IF(AH12>=Assumptions!$C$13,'Rental CF'!AI$29,0) -> 0
B16: LIHTC Equity | E16: =IF(E12=Assumptions!$C$10,'Sources and Uses'!$C$8,0) -> 10635591 | F16: =IF(F12=Assumptions!$C$10,'Sources and Uses'!$C$8,0) -> 0 | G16: =IF(G12=Assumptions!$C$10,'Sources and Uses'!$C$8,0) -> 0 | H16: =IF(H12=Assumptions!$C$10,'Sources and Uses'!$C$8,0) -> 0 | I16: =IF(I12=Assumptions!$C$10,'Sources and Uses'!$C$8,0) -> 0 | J16: =IF(J12=Assumptions!$C$10,'Sources and Uses'!$C$8,0) -> 0 | K16: =IF(K12=Assumptions!$C$10,'Sources and Uses'!$C$8,0) -> 0 | L16: =IF(L12=Assumptions!$C$10,'Sources and Uses'!$C$8,0) -> 0 | ... AH16: =IF(AH12=Assumptions!$C$10,'Sources and Uses'!$C$8,0) -> 0
B17: Loan draws | E17: =-E28*$D$6 -> 8462988.1 | F17: =-F28*$D$6 -> 8462987.3 | G17: =-G28*$D$6 -> 8462987.3 | H17: =-H28*$D$6 -> 8462987.3 | I17: =-I28*$D$6 -> 8462987.3 | J17: =-J28*$D$6 -> 8462987.3 | K17: =-K28*$D$6 -> 8462987.3 | L17: =-L28*$D$6 -> 8462987.3 | ... AH17: =-AH28*$D$6 -> 1412777.5
B18: Defered Developer Fee | E18: =IF(E12=Assumptions!$C$10,Assumptions!$D$63,IF(AND(E12>=Assumptions!$C$10,E12<=EOMONTH(Assumptions!$C$10,Assumptions!$C$11)),Assumptions!$D$64/Assumptions!$C$11,IF(E12=EOMONTH(Assumptions!$C$13,Assumptions!$E$65),Assumptions!$D$65,0))) -> 0 | F18: =IF(F12=Assumptions!$C$10,Assumptions!$D$63,IF(AND(F12>=Assumptions!$C$10,F12<=EOMONTH(Assumptions!$C$10,Assumptions!$C$11)),Assumptions!$D$64/Assumptions!$C$11,IF(F12=EOMONTH(Assumptions!$C$13,Assumptions!$E$65),Assumptions!$D$65,0))) -> 36583.333 | G18: =IF(G12=Assumptions!$C$10,Assumptions!$D$63,IF(AND(G12>=Assumptions!$C$10,G12<=EOMONTH(Assumptions!$C$10,Assumptions!$C$11)),Assumptions!$D$64/Assumptions!$C$11,IF(G12=EOMONTH(Assumptions!$C$13,Assumptions!$E$65),Assumptions!$D$65,0))) -> 36583.333 | H18: =IF(H12=Assumptions!$C$10,Assumptions!$D$63,IF(AND(H12>=Assumptions!$C$10,H12<=EOMONTH(Assumptions!$C$10,Assumptions!$C$11)),Assumptions!$D$64/Assumptions!$C$11,IF(H12=EOMONTH(Assumptions!$C$13,Assumptions!$E$65),Assumptions!$D$65,0))) -> 36583.333 | I18: =IF(I12=Assumptions!$C$10,Assumptions!$D$63,IF(AND(I12>=Assumptions!$C$10,I12<=EOMONTH(Assumptions!$C$10,Assumptions!$C$11)),Assumptions!$D$64/Assumptions!$C$11,IF(I12=EOMONTH(Assumptions!$C$13,Assumptions!$E$65),Assumptions!$D$65,0))) -> 36583.333 | J18: =IF(J12=Assumptions!$C$10,Assumptions!$D$63,IF(AND(J12>=Assumptions!$C$10,J12<=EOMONTH(Assumptions!$C$10,Assumptions!$C$11)),Assumptions!$D$64/Assumptions!$C$11,IF(J12=EOMONTH(Assumptions!$C$13,Assumptions!$E$65),Assumptions!$D$65,0))) -> 36583.333 | K18: =IF(K12=Assumptions!$C$10,Assumptions!$D$63,IF(AND(K12>=Assumptions!$C$10,K12<=EOMONTH(Assumptions!$C$10,Assumptions!$C$11)),Assumptions!$D$64/Assumptions!$C$11,IF(K12=EOMONTH(Assumptions!$C$13,Assumptions!$E$65),Assumptions!$D$65,0))) -> 36583.333 | L18: =IF(L12=Assumptions!$C$10,Assumptions!$D$63,IF(AND(L12>=Assumptions!$C$10,L12<=EOMONTH(Assumptions!$C$10,Assumptions!$C$11)),Assumptions!$D$64/Assumptions!$C$11,IF(L12=EOMONTH(Assumptions!$C$13,Assumptions!$E$65),Assumptions!$D$65,0))) -> 36583.333 | ... AH18: =IF(AH12=Assumptions!$C$10,Assumptions!$D$63,IF(AND(AH12>=Assumptions!$C$10,AH12<=EOMONTH(Assumptions!$C$10,Assumptions!$C$11)),Assumptions!$D$64/Assumptions!$C$11,IF(AH12=EOMONTH(Assumptions!$C$13,Assumptions!$E$65),Assumptions!$D$65,0))) -> 0
B20: Total Inflow | E20: =SUM(E15:E19) -> 19098579 | F20: =SUM(F15:F19) -> 8499570.6 | G20: =SUM(G15:G19) -> 8499570.6 | H20: =SUM(H15:H19) -> 8499570.6 | I20: =SUM(I15:I19) -> 8499570.6 | J20: =SUM(J15:J19) -> 8499570.6 | K20: =SUM(K15:K19) -> 8499570.6 | L20: =SUM(L15:L19) -> 8499570.6 | ... AH20: =SUM(AH15:AH19) -> 1412777.5
B22: Ouflow
B24: Acquisition Cost | E24: =Budget!J122 -> -1 | F24: =Budget!K122 -> 0 | G24: =Budget!L122 -> 0 | H24: =Budget!M122 -> 0 | I24: =Budget!N122 -> 0 | J24: =Budget!O122 -> 0 | K24: =Budget!P122 -> 0 | L24: =Budget!Q122 -> 0 | ... AH24: =Budget!AM122 -> 0
B25: Soft & Hard Cost | E25: =_xlfn.XLOOKUP('Development CF'!E12,Budget!$J$7:$OO$7,Budget!$J$50:$OO$50) -> -8594683.3 | F25: =_xlfn.XLOOKUP('Development CF'!F12,Budget!$J$7:$OO$7,Budget!$J$50:$OO$50) -> -8594683.3 | G25: =_xlfn.XLOOKUP('Development CF'!G12,Budget!$J$7:$OO$7,Budget!$J$50:$OO$50) -> -8594683.3 | H25: =_xlfn.XLOOKUP('Development CF'!H12,Budget!$J$7:$OO$7,Budget!$J$50:$OO$50) -> -8594683.3 | I25: =_xlfn.XLOOKUP('Development CF'!I12,Budget!$J$7:$OO$7,Budget!$J$50:$OO$50) -> -8594683.3 | J25: =_xlfn.XLOOKUP('Development CF'!J12,Budget!$J$7:$OO$7,Budget!$J$50:$OO$50) -> -8594683.3 | K25: =_xlfn.XLOOKUP('Development CF'!K12,Budget!$J$7:$OO$7,Budget!$J$50:$OO$50) -> -8594683.3 | L25: =_xlfn.XLOOKUP('Development CF'!L12,Budget!$J$7:$OO$7,Budget!$J$50:$OO$50) -> -8594683.3 | ... AH25: =_xlfn.XLOOKUP('Development CF'!AH12,Budget!$J$7:$OO$7,Budget!$J$50:$OO$50) -> 0
B26: Finance Cost | E26: =_xlfn.XLOOKUP(E12,Budget!$J$7:$OO$7,Budget!$J$58:$OO$58) -> -1722271.5 | F26: =_xlfn.XLOOKUP(F12,Budget!$J$7:$OO$7,Budget!$J$58:$OO$58) -> -1722271.5 | G26: =_xlfn.XLOOKUP(G12,Budget!$J$7:$OO$7,Budget!$J$58:$OO$58) -> -1722271.5 | H26: =_xlfn.XLOOKUP(H12,Budget!$J$7:$OO$7,Budget!$J$58:$OO$58) -> -1722271.5 | I26: =_xlfn.XLOOKUP(I12,Budget!$J$7:$OO$7,Budget!$J$58:$OO$58) -> -1722271.5 | J26: =_xlfn.XLOOKUP(J12,Budget!$J$7:$OO$7,Budget!$J$58:$OO$58) -> -1722271.5 | K26: =_xlfn.XLOOKUP(K12,Budget!$J$7:$OO$7,Budget!$J$58:$OO$58) -> -1722271.5 | L26: =_xlfn.XLOOKUP(L12,Budget!$J$7:$OO$7,Budget!$J$58:$OO$58) -> -1722271.5 | ... AH26: =_xlfn.XLOOKUP(AH12,Budget!$J$7:$OO$7,Budget!$J$58:$OO$58) -> -1722271.5
B28: Total Outflow | E28: =SUM(E24:E27) -> -10316956 | F28: =SUM(F25:F27) -> -10316955 | G28: =SUM(G25:G27) -> -10316955 | H28: =SUM(H25:H27) -> -10316955 | I28: =SUM(I25:I27) -> -10316955 | J28: =SUM(J25:J27) -> -10316955 | K28: =SUM(K25:K27) -> -10316955 | L28: =SUM(L25:L27) -> -10316955 | M28: =SUM(M25:M27) -> -10316955 | ... AH28: =SUM(AH25:AH27) -> -1722271.5
B30: Net Cash Flow | E30: =E20+E28 -> 8781623.6 | F30: =F20+F28 -> -1817384.2 | G30: =G20+G28 -> -1817384.2 | H30: =H20+H28 -> -1817384.2 | I30: =I20+I28 -> -1817384.2 | J30: =J20+J28 -> -1817384.2 | K30: =K20+K28 -> -1817384.2 | L30: =L20+L28 -> -1817384.2 | ... AH30: =AH20+AH28 -> -309493.99
B33: IRR | C33: =(1+XIRR(E30:AH30,E12:AH12))^(1/12)-1 -> 0.20661034

Sheet Rental CF
B2: Rental Cash Flow
B3: ALL figures are in USD
F5: 1 | G5: 2 | H5: 3 | I5: 4 | J5: 5 | K5: 6 | L5: 7 | M5: 8 | N5: 9 | O5: 10 | P5: 11 | Q5: 12 | R5: 13 | S5: 14 | T5: 15 | U5: 16 | V5: 17 | W5: 18 | X5: 19 | Y5: 20 | Z5: 21 | AA5: 22 | AB5: 23 | AC5: 24 | AD5: 25 | AE5: 26 | AF5: 27 | AG5: 28 | AH5: 29 | AI5: 30
F6: =YEAR(F7) -> 2029 | G6: =YEAR(G7) -> 2030 | H6: =YEAR(H7) -> 2031 | I6: =YEAR(I7) -> 2032 | J6: =YEAR(J7) -> 2033 | K6: =YEAR(K7) -> 2034 | L6: =YEAR(L7) -> 2035 | M6: =YEAR(M7) -> 2036 | ... AI6: =YEAR(AI7) -> 2058
F7: =Assumptions!C13 -> 47330 | G7: =EOMONTH(F7,12) -> 47695 | H7: =EOMONTH(G7,12) -> 48060 | I7: =EOMONTH(H7,12) -> 48426 | J7: =EOMONTH(I7,12) -> 48791 | K7: =EOMONTH(J7,12) -> 49156 | L7: =EOMONTH(K7,12) -> 49521 | M7: =EOMONTH(L7,12) -> 49887 | N7: =EOMONTH(M7,12) -> 50252 | ... AI7: =EOMONTH(AH7,12) -> 57922
C8: Escalator (%)
B9: Potential Gross Income
B10: Total Annual Rental Income | C10: 0.02 | F10: ='Unit Mix'!I81 -> 7752009.3 | G10: =F10+(F10*$C10) -> 7907049.4 | H10: =G10+(G10*$C10) -> 8065190.4 | I10: =H10+(H10*$C10) -> 8226494.2 | J10: =I10+(I10*$C10) -> 8391024.1 | K10: =J10+(J10*$C10) -> 8558844.6 | L10: =K10+(K10*$C10) -> 8730021.5 | M10: =L10+(L10*$C10) -> 8904621.9 | N10: =M10+(M10*$C10) -> 9082714.4 | ... AI10: =AH10+(AH10*$C10) -> 13766364
B11: Parking | C11: 0.02 | F11: =Mortgage!D6 -> 45000 | G11: =F11+(F11*$C11) -> 45900 | H11: =G11+(G11*$C11) -> 46818 | I11: =H11+(H11*$C11) -> 47754.36 | J11: =I11+(I11*$C11) -> 48709.447 | K11: =J11+(J11*$C11) -> 49683.636 | L11: =K11+(K11*$C11) -> 50677.309 | M11: =L11+(L11*$C11) -> 51690.855 | N11: =M11+(M11*$C11) -> 52724.672 | ... AI11: =AH11+(AH11*$C11) -> 79913.011
B12: Commercial | C12: 0.02 | F12: =Mortgage!D7 -> 0 | G12: =F12+(F12*$C12) -> 0 | H12: =G12+(G12*$C12) -> 0 | I12: =H12+(H12*$C12) -> 0 | J12: =I12+(I12*$C12) -> 0 | K12: =J12+(J12*$C12) -> 0 | L12: =K12+(K12*$C12) -> 0 | M12: =L12+(L12*$C12) -> 0 | N12: =M12+(M12*$C12) -> 0 | ... AI12: =AH12+(AH12*$C12) -> 0
B13: Community Facility | C13: 0.02 | F13: =Mortgage!D8 -> 0 | G13: =F13+(F13*$C13) -> 0 | H13: =G13+(G13*$C13) -> 0 | I13: =H13+(H13*$C13) -> 0 | J13: =I13+(I13*$C13) -> 0 | K13: =J13+(J13*$C13) -> 0 | L13: =K13+(K13*$C13) -> 0 | M13: =L13+(L13*$C13) -> 0 | N13: =M13+(M13*$C13) -> 0 | ... AI13: =AH13+(AH13*$C13) -> 0
B14: Laundry | C14: 0.02 | F14: =Mortgage!D9 -> 39480 | G14: =F14+(F14*$C14) -> 40269.6 | H14: =G14+(G14*$C14) -> 41074.992 | I14: =H14+(H14*$C14) -> 41896.492 | J14: =I14+(I14*$C14) -> 42734.422 | K14: =J14+(J14*$C14) -> 43589.11 | L14: =K14+(K14*$C14) -> 44460.892 | M14: =L14+(L14*$C14) -> 45350.11 | N14: =M14+(M14*$C14) -> 46257.112 | ... AI14: =AH14+(AH14*$C14) -> 70110.348
B15: Total Potential Gross Income: | F15: =SUM(F10:F14) -> 7836489.3 | G15: =SUM(G10:G14) -> 7993219 | H15: =SUM(H10:H14) -> 8153083.4 | I15: =SUM(I10:I14) -> 8316145.1 | J15: =SUM(J10:J14) -> 8482468 | K15: =SUM(K10:K14) -> 8652117.4 | L15: =SUM(L10:L14) -> 8825159.7 | M15: =SUM(M10:M14) -> 9001662.9 | ... AI15: =SUM(AI10:AI14) -> 13916388
B16: Vacancy Allowance
B17: Total Annual Rental Income | D17: =Mortgage!C13 -> 0.05 | F17: =-(F10*$D17) -> -387600.46 | G17: =-(G10*$D17) -> -395352.47 | H17: =-(H10*$D17) -> -403259.52 | I17: =-(I10*$D17) -> -411324.71 | J17: =-(J10*$D17) -> -419551.21 | K17: =-(K10*$D17) -> -427942.23 | L17: =-(L10*$D17) -> -436501.07 | M17: =-(M10*$D17) -> -445231.1 | ... AI17: =-(AI10*$D17) -> -688318.22
B18: Parking | D18: 0.05 | F18: =-(F11*$D18) -> -2250 | G18: =-(G11*$D18) -> -2295 | H18: =-(H11*$D18) -> -2340.9 | I18: =-(I11*$D18) -> -2387.718 | J18: =-(J11*$D18) -> -2435.4724 | K18: =-(K11*$D18) -> -2484.1818 | L18: =-(L11*$D18) -> -2533.8654 | M18: =-(M11*$D18) -> -2584.5428 | ... AI18: =-(AI11*$D18) -> -3995.6506
B19: Commercial | D19: =Mortgage!C15 -> 0.1 | F19: =-(F12*$D19) -> 0 | G19: =-(G12*$D19) -> 0 | H19: =-(H12*$D19) -> 0 | I19: =-(I12*$D19) -> 0 | J19: =-(J12*$D19) -> 0 | K19: =-(K12*$D19) -> 0 | L19: =-(L12*$D19) -> 0 | M19: =-(M12*$D19) -> 0 | ... AI19: =-(AI12*$D19) -> 0
B20: Community Facility | D20: =Mortgage!C16 -> 0.1 | F20: =-(F13*$D20) -> 0 | G20: =-(G13*$D20) -> 0 | H20: =-(H13*$D20) -> 0 | I20: =-(I13*$D20) -> 0 | J20: =-(J13*$D20) -> 0 | K20: =-(K13*$D20) -> 0 | L20: =-(L13*$D20) -> 0 | M20: =-(M13*$D20) -> 0 | ... AI20: =-(AI13*$D20) -> 0
